Workbook

Sheet KPI_Summary
A1: E-Commerce Sales Analysis - KPI Summary (2024)
A2: All figures are formulas over Orders_Clean / Payments_Clean. Data is synthetic sample data. Cancelled orders are included, as in the dashboard.
A4: KPI | B4: Value
A5: Total Sales | B5: =SUM(Orders_Clean!$N$2:$N$533) -> 4278560
A6: Total Profit | B6: =SUM(Orders_Clean!$O$2:$O$533) -> 856320
A7: Total Orders | B7: =COUNTA(Orders_Clean!$A$2:$A$533) -> 532
A8: Total Customers | B8: =SUMPRODUCT(1/COUNTIF(Orders_Clean!$G$2:$G$533,Orders_Clean!$G$2:$G$533)) -> 487
A9: Total Transactions | B9: =COUNTA(Payments_Clean!$A$2:$A$1564) -> 1563
A10: Avg Order Value | B10: =B5/B7 -> 8042.406
A11: Profit Margin % | B11: =B6/B5 -> 0.2001421
A12: Avg Transaction Value | B12: =B5/B9 -> 2737.4024
A15: Category | B15: Sales | C15: Profit | D15: Orders | E15: Share %
A16: Electronics | B16: =SUMIFS(Orders_Clean!$N$2:$N$533,Orders_Clean!$L$2:$L$533,A16) -> 1797400 | C16: =SUMIFS(Orders_Clean!$O$2:$O$533,Orders_Clean!$L$2:$L$533,A16) -> 410000 | D16: =COUNTIFS(Orders_Clean!$L$2:$L$533,A16) -> 174 | E16: =B16/$B$5 -> 0.42009461
A17: Furniture | B17: =SUMIFS(Orders_Clean!$N$2:$N$533,Orders_Clean!$L$2:$L$533,A17) -> 1408650 | C17: =SUMIFS(Orders_Clean!$O$2:$O$533,Orders_Clean!$L$2:$L$533,A17) -> 262000 | D17: =COUNTIFS(Orders_Clean!$L$2:$L$533,A17) -> 144 | E17: =B17/$B$5 -> 0.3292346
A18: Clothing | B18: =SUMIFS(Orders_Clean!$N$2:$N$533,Orders_Clean!$L$2:$L$533,A18) -> 1072510 | C18: =SUMIFS(Orders_Clean!$O$2:$O$533,Orders_Clean!$L$2:$L$533,A18) -> 184320 | D18: =COUNTIFS(Orders_Clean!$L$2:$L$533,A18) -> 214 | E18: =B18/$B$5 -> 0.25067079
A20: Quarter | B20: Sales | C20: Profit | D20: Orders | E20: Share %
A21: Q1 | B21: =SUMIFS(Orders_Clean!$N$2:$N$533,Orders_Clean!$F$2:$F$533,A21) -> 841683 | C21: =SUMIFS(Orders_Clean!$O$2:$O$533,Orders_Clean!$F$2:$F$533,A21) -> 161437 | D21: =COUNTIFS(Orders_Clean!$F$2:$F$533,A21) -> 105 | E21: =B21/$B$5 -> 0.19672109
A22: Q2 | B22: =SUMIFS(Orders_Clean!$N$2:$N$533,Orders_Clean!$F$2:$F$533,A22) -> 1022045 | C22: =SUMIFS(Orders_Clean!$O$2:$O$533,Orders_Clean!$F$2:$F$533,A22) -> 205512 | D22: =COUNTIFS(Orders_Clean!$F$2:$F$533,A22) -> 127 | E22: =B22/$B$5 -> 0.23887593
A23: Q3 | B23: =SUMIFS(Orders_Clean!$N$2:$N$533,Orders_Clean!$F$2:$F$533,A23) -> 1162326 | C23: =SUMIFS(Orders_Clean!$O$2:$O$533,Orders_Clean!$F$2:$F$533,A23) -> 222298 | D23: =COUNTIFS(Orders_Clean!$F$2:$F$533,A23) -> 145 | E23: =B23/$B$5 -> 0.2716629
A24: Q4 | B24: =SUMIFS(Orders_Clean!$N$2:$N$533,Orders_Clean!$F$2:$F$533,A24) -> 1252506 | C24: =SUMIFS(Orders_Clean!$O$2:$O$533,Orders_Clean!$F$2:$F$533,A24) -> 267073 | D24: =COUNTIFS(Orders_Clean!$F$2:$F$533,A24) -> 155 | E24: =B24/$B$5 -> 0.29274008
A26: Region | B26: Sales | C26: Profit | D26: Orders | E26: Share %
A27: West | B27: =SUMIFS(Orders_Clean!$N$2:$N$533,Orders_Clean!$R$2:$R$533,A27) -> 1369139 | C27: =SUMIFS(Orders_Clean!$O$2:$O$533,Orders_Clean!$R$2:$R$533,A27) -> 268037 | D27: =COUNTIFS(Orders_Clean!$R$2:$R$533,A27) -> 170 | E27: =B27/$B$5 -> 0.31999995
A28: North | B28: =SUMIFS(Orders_Clean!$N$2:$N$533,Orders_Clean!$R$2:$R$533,A28) -> 1198000 | C28: =SUMIFS(Orders_Clean!$O$2:$O$533,Orders_Clean!$R$2:$R$533,A28) -> 244380 | D28: =COUNTIFS(Orders_Clean!$R$2:$R$533,A28) -> 150 | E28: =B28/$B$5 -> 0.28000075
A29: South | B29: =SUMIFS(Orders_Clean!$N$2:$N$533,Orders_Clean!$R$2:$R$533,A29) -> 941281 | C29: =SUMIFS(Orders_Clean!$O$2:$O$533,Orders_Clean!$R$2:$R$533,A29) -> 193644 | D29: =COUNTIFS(Orders_Clean!$R$2:$R$533,A29) -> 116 | E29: =B29/$B$5 -> 0.21999949
A30: East | B30: =SUMIFS(Orders_Clean!$N$2:$N$533,Orders_Clean!$R$2:$R$533,A30) -> 770140 | C30: =SUMIFS(Orders_Clean!$O$2:$O$533,Orders_Clean!$R$2:$R$533,A30) -> 150259 | D30: =COUNTIFS(Orders_Clean!$R$2:$R$533,A30) -> 96 | E30: =B30/$B$5 -> 0.17999981
A32: Status | B32: Sales | C32: Profit | D32: Orders | E32: Share %
A33: Delivered | B33: =SUMIFS(Orders_Clean!$N$2:$N$533,Orders_Clean!$S$2:$S$533,A33) -> 3421860 | C33: =SUMIFS(Orders_Clean!$O$2:$O$533,Orders_Clean!$S$2:$S$533,A33) -> 686750 | D33: =COUNTIFS(Orders_Clean!$S$2:$S$533,A33) -> 423 | E33: =B33/$B$5 -> 0.79976908
A34: Shipped | B34: =SUMIFS(Orders_Clean!$N$2:$N$533,Orders_Clean!$S$2:$S$533,A34) -> 565146 | C34: =SUMIFS(Orders_Clean!$O$2:$O$533,Orders_Clean!$S$2:$S$533,A34) -> 104783 | D34: =COUNTIFS(Orders_Clean!$S$2:$S$533,A34) -> 74 | E34: =B34/$B$5 -> 0.1320879
A35: Cancelled | B35: =SUMIFS(Orders_Clean!$N$2:$N$533,Orders_Clean!$S$2:$S$533,A35) -> 291554 | C35: =SUMIFS(Orders_Clean!$O$2:$O$533,Orders_Clean!$S$2:$S$533,A35) -> 64787 | D35: =COUNTIFS(Orders_Clean!$S$2:$S$533,A35) -> 35 | E35: =B35/$B$5 -> 0.06814302
A37: Segment | B37: Sales | C37: Profit | D37: Orders | E37: Share %
A38: New | B38: =SUMIFS(Orders_Clean!$N$2:$N$533,Orders_Clean!$I$2:$I$533,A38) -> 1970002 | C38: =SUMIFS(Orders_Clean!$O$2:$O$533,Orders_Clean!$I$2:$I$533,A38) -> 409613 | D38: =COUNTIFS(Orders_Clean!$I$2:$I$533,A38) -> 282 | E38: =B38/$B$5 -> 0.46043575
A39: Returning | B39: =SUMIFS(Orders_Clean!$N$2:$N$533,Orders_Clean!$I$2:$I$533,A39) -> 1204731 | C39: =SUMIFS(Orders_Clean!$O$2:$O$533,Orders_Clean!$I$2:$I$533,A39) -> 227396 | D39: =COUNTIFS(Orders_Clean!$I$2:$I$533,A39) -> 166 | E39: =B39/$B$5 -> 0.28157394
A40: VIP | B40: =SUMIFS(Orders_Clean!$N$2:$N$533,Orders_Clean!$I$2:$I$533,A40) -> 1103827 | C40: =SUMIFS(Orders_Clean!$O$2:$O$533,Orders_Clean!$I$2:$I$533,A40) -> 219311 | D40: =COUNTIFS(Orders_Clean!$I$2:$I$533,A40) -> 84 | E40: =B40/$B$5 -> 0.25799031
A42: State | B42: Sales | C42: Profit | D42: Orders | E42: Share %
A43: Maharashtra | B43: =SUMIFS(Orders_Clean!$N$2:$N$533,Orders_Clean!$Q$2:$Q$533,A43) -> 845210 | C43: =SUMIFS(Orders_Clean!$O$2:$O$533,Orders_Clean!$Q$2:$Q$533,A43) -> 160566 | D43: =COUNTIFS(Orders_Clean!$Q$2:$Q$533,A43) -> 105 | E43: =B43/$B$5 -> 0.19754544
A44: Uttar Pradesh | B44: =SUMIFS(Orders_Clean!$N$2:$N$533,Orders_Clean!$Q$2:$Q$533,A44) -> 632780 | C44: =SUMIFS(Orders_Clean!$O$2:$O$533,Orders_Clean!$Q$2:$Q$533,A44) -> 130164 | D44: =COUNTIFS(Orders_Clean!$Q$2:$Q$533,A44) -> 79 | E44: =B44/$B$5 -> 0.14789555
A45: Karnataka | B45: =SUMIFS(Orders_Clean!$N$2:$N$533,Orders_Clean!$Q$2:$Q$533,A45) -> 421360 | C45: =SUMIFS(Orders_Clean!$O$2:$O$533,Orders_Clean!$Q$2:$Q$533,A45) -> 85954 | D45: =COUNTIFS(Orders_Clean!$Q$2:$Q$533,A45) -> 52 | E45: =B45/$B$5 -> 0.098481732
A46: Tamil Nadu | B46: =SUMIFS(Orders_Clean!$N$2:$N$533,Orders_Clean!$Q$2:$Q$533,A46) -> 378920 | C46: =SUMIFS(Orders_Clean!$O$2:$O$533,Orders_Clean!$Q$2:$Q$533,A46) -> 77951 | D46: =COUNTIFS(Orders_Clean!$Q$2:$Q$533,A46) -> 47 | E46: =B46/$B$5 -> 0.088562507
A47: Gujarat | B47: =SUMIFS(Orders_Clean!$N$2:$N$533,Orders_Clean!$Q$2:$Q$533,A47) -> 312450 | C47: =SUMIFS(Orders_Clean!$O$2:$O$533,Orders_Clean!$Q$2:$Q$533,A47) -> 63814 | D47: =COUNTIFS(Orders_Clean!$Q$2:$Q$533,A47) -> 39 | E47: =B47/$B$5 -> 0.073026906
A48: West Bengal | B48: =SUMIFS(Orders_Clean!$N$2:$N$533,Orders_Clean!$Q$2:$Q$533,A48) -> 300000 | C48: =SUMIFS(Orders_Clean!$O$2:$O$533,Orders_Clean!$Q$2:$Q$533,A48) -> 65340 | D48: =COUNTIFS(Orders_Clean!$Q$2:$Q$533,A48) -> 37 | E48: =B48/$B$5 -> 0.070117049
...

Sheet Orders_Clean
A1: OrderID | B1: OrderDate | C1: Year | D1: Month | E1: MonthName | F1: Quarter | G1: CustomerID | H1: CustomerName | I1: Segment | J1: ProductID | K1: ProductName | L1: Category | M1: Qty | N1: Sales | O1: Profit | P1: City | Q1: State | R1: Region | S1: Status | T1: PaymentCount | U1: PaymentModes
A2: ORD0001 | B2: 45292 | C2: 2024 | D2: 1 | E2: Jan | F2: Q1 | G2: C0001 | H2: Sakshi Verma | I2: New | J2: P032 | K2: T-Shirt | L2: Clothing | M2: 1 | N2: 651 | O2: 94 | P2: New Delhi | Q2: Delhi | R2: North | S2: Delivered | T2: 1 | U2: Cards
A3: ORD0002 | B3: 45293 | C3: 2024 | D3: 1 | E3: Jan | F3: Q1 | G3: C0002 | H3: Ramesh Das | I3: New | J3: P029 | K3: Bean Bag | L3: Furniture | M3: 1 | N3: 7370 | O3: 989 | P3: Pune | Q3: Maharashtra | R3: West | S3: Delivered | T3: 3 | U3: Cards + EMI
A4: ORD0003 | B4: 45293 | C4: 2024 | D4: 1 | E4: Jan | F4: Q1 | G4: C0003 | H4: Gaurav Agarwal | I4: New | J4: P037 | K4: Saree | L4: Clothing | M4: 4 | N4: 10366 | O4: 1915 | P4: Bengaluru | Q4: Karnataka | R4: South | S4: Delivered | T4: 5 | U4: Cards + UPI
A5: ORD0004 | B5: 45293 | C5: 2024 | D5: 1 | E5: Jan | F5: Q1 | G5: C0004 | H5: Komal Kulkarni | I5: New | J5: P038 | K5: Track Pants | L5: Clothing | M5: 2 | N5: 3855 | O5: 582 | P5: Ahmedabad | Q5: Gujarat | R5: West | S5: Delivered | T5: 3 | U5: UPI
A6: ORD0005 | B6: 45294 | C6: 2024 | D6: 1 | E6: Jan | F6: Q1 | G6: C0005 | H6: Manish Tiwari | I6: New | J6: P002 | K6: Laptop Dell | L6: Electronics | M6: 1 | N6: 7723 | O6: 2790 | P6: Bengaluru | Q6: Karnataka | R6: South | S6: Delivered | T6: 4 | U6: EMI
A7: ORD0006 | B7: 45294 | C7: 2024 | D7: 1 | E7: Jan | F7: Q1 | G7: C0006 | H7: Tanvi Verma | I7: New | J7: P004 | K7: Smart Watch | L7: Electronics | M7: 4 | N7: 6411 | O7: 1218 | P7: New Delhi | Q7: Delhi | R7: North | S7: Delivered | T7: 2 | U7: UPI
A8: ORD0007 | B8: 45295 | C8: 2024 | D8: 1 | E8: Jan | F8: Q1 | G8: C0007 | H8: Anjali Rawat | I8: New | J8: P002 | K8: Laptop Dell | L8: Electronics | M8: 1 | N8: 6374 | O8: 2384 | P8: Ludhiana | Q8: Punjab | R8: North | S8: Delivered | T8: 5 | U8: Cards + Cash + UPI
A9: ORD0008 | B9: 45295 | C9: 2024 | D9: 1 | E9: Jan | F9: Q1 | G9: C0008 | H9: Pranav Yadav | I9: Returning | J9: P004 | K9: Smart Watch | L9: Electronics | M9: 2 | N9: 4230 | O9: 823 | P9: Nagpur | Q9: Maharashtra | R9: West | S9: Cancelled | T9: 1 | U9: Cash
A10: ORD0009 | B10: 45296 | C10: 2024 | D10: 1 | E10: Jan | F10: Q1 | G10: C0009 | H10: Aishwarya Tiwari | I10: New | J10: P034 | K10: Jeans | L10: Clothing | M10: 2 | N10: 5865 | O10: 787 | P10: Pune | Q10: Maharashtra | R10: West | S10: Delivered | T10: 2 | U10: UPI
A11: ORD0010 | B11: 45296 | C11: 2024 | D11: 1 | E11: Jan | F11: Q1 | G11: C0010 | H11: Swati Srivastava | I11: VIP | J11: P035 | K11: Formal Shirt | L11: Clothing | M11: 2 | N11: 4313 | O11: 567 | P11: Kochi | Q11: Kerala | R11: South | S11: Delivered | T11: 4 | U11: Cards + Cash + UPI
A12: ORD0011 | B12: 45296 | C12: 2024 | D12: 1 | E12: Jan | F12: Q1 | G12: C0011 | H12: Komal Pillai | I12: New | J12: P038 | K12: Track Pants | L12: Clothing | M12: 2 | N12: 7682 | O12: 1048 | P12: Patna | Q12: Bihar | R12: East | S12: Delivered | T12: 2 | U12: Cards + UPI
A13: ORD0012 | B13: 45299 | C13: 2024 | D13: 1 | E13: Jan | F13: Q1 | G13: C0012 | H13: Karan Jain | I13: New | J13: P030 | K13: Men's Jacket | L13: Clothing | M13: 1 | N13: 2312 | O13: 640 | P13: Ranchi | Q13: Jharkhand | R13: East | S13: Delivered | T13: 2 | U13: UPI
... A533: ORD0532 | B533: 45656 | C533: 2024 | D533: 12 | E533: Dec | F533: Q4 | G533: C0487 | H533: Varun Sharma | I533: New | J533: P028 | K533: Dressing Table | L533: Furniture | M533: 1 | N533: 6614 | O533: 885 | P533: Gurugram | Q533: Haryana | R533: North | S533: Shipped | T533: 3 | U533: EMI

Sheet Payments_Clean
A1: TransactionID | B1: OrderID | C1: OrderDate | D1: Category | E1: State | F1: PaymentMode | G1: Amount
A2: TXN00001 | B2: ORD0001 | C2: 45292 | D2: Clothing | E2: Delhi | F2: Cards | G2: 651
A3: TXN00002 | B3: ORD0002 | C3: 45293 | D3: Furniture | E3: Maharashtra | F3: EMI | G3: 4764
A4: TXN00003 | B4: ORD0002 | C4: 45293 | D4: Furniture | E4: Maharashtra | F4: Cards | G4: 827
A5: TXN00004 | B5: ORD0002 | C5: 45293 | D5: Furniture | E5: Maharashtra | F5: EMI | G5: 1779
A6: TXN00005 | B6: ORD0003 | C6: 45293 | D6: Clothing | E6: Karnataka | F6: UPI | G6: 3262
A7: TXN00006 | B7: ORD0003 | C7: 45293 | D7: Clothing | E7: Karnataka | F7: Cards | G7: 1973
A8: TXN00007 | B8: ORD0003 | C8: 45293 | D8: Clothing | E8: Karnataka | F8: UPI | G8: 650
A9: TXN00008 | B9: ORD0003 | C9: 45293 | D9: Clothing | E9: Karnataka | F9: UPI | G9: 2324
A10: TXN00009 | B10: ORD0003 | C10: 45293 | D10: Clothing | E10: Karnataka | F10: UPI | G10: 2157
A11: TXN00010 | B11: ORD0004 | C11: 45293 | D11: Clothing | E11: Gujarat | F11: UPI | G11: 967
A12: TXN00011 | B12: ORD0004 | C12: 45293 | D12: Clothing | E12: Gujarat | F12: UPI | G12: 1105
A13: TXN00012 | B13: ORD0004 | C13: 45293 | D13: Clothing | E13: Gujarat | F13: UPI | G13: 1783
... A1564: TXN01563 | B1564: ORD0532 | C1564: 45656 | D1564: Furniture | E1564: Haryana | F1564: EMI | G1564: 4198
